[2025-06-16T13:42:59.973+0000] {taskinstance.py:1125} INFO - Dependencies all met for dep_context=non-requeueable deps ti=<TaskInstance: user_automation.stream_data_from_api manual__2025-06-16T13:42:56.301505+00:00 [queued]>
[2025-06-16T13:42:59.982+0000] {taskinstance.py:1125} INFO - Dependencies all met for dep_context=requeueable deps ti=<TaskInstance: user_automation.stream_data_from_api manual__2025-06-16T13:42:56.301505+00:00 [queued]>
[2025-06-16T13:42:59.982+0000] {taskinstance.py:1331} INFO - Starting attempt 1 of 1
[2025-06-16T13:43:00.020+0000] {taskinstance.py:1350} INFO - Executing <Task(PythonOperator): stream_data_from_api> on 2025-06-16 13:42:56.301505+00:00
[2025-06-16T13:43:00.043+0000] {standard_task_runner.py:57} INFO - Started process 178 to run task
[2025-06-16T13:43:00.050+0000] {standard_task_runner.py:84} INFO - Running: ['***', 'tasks', 'run', 'user_automation', 'stream_data_from_api', 'manual__2025-06-16T13:42:56.301505+00:00', '--job-id', '30', '--raw', '--subdir', 'DAGS_FOLDER/kafka_stream.py', '--cfg-path', '/tmp/tmp88398f8e']
[2025-06-16T13:43:00.054+0000] {standard_task_runner.py:85} INFO - Job 30: Subtask stream_data_from_api
[2025-06-16T13:43:00.137+0000] {task_command.py:410} INFO - Running <TaskInstance: user_automation.stream_data_from_api manual__2025-06-16T13:42:56.301505+00:00 [running]> on host d6a0e3e86e16
[2025-06-16T13:43:00.798+0000] {taskinstance.py:1568} INFO - Exporting env vars: AIRFLOW_CTX_DAG_OWNER='airscholar' AIRFLOW_CTX_DAG_ID='user_automation' AIRFLOW_CTX_TASK_ID='stream_data_from_api' AIRFLOW_CTX_EXECUTION_DATE='2025-06-16T13:42:56.301505+00:00' AIRFLOW_CTX_TRY_NUMBER='1' AIRFLOW_CTX_DAG_RUN_ID='manual__2025-06-16T13:42:56.301505+00:00'
[2025-06-16T13:43:01.266+0000] {conn.py:396} INFO - <BrokerConnection client_id=kafka-python-producer-1, node_id=bootstrap-0 host=broker:29092 <connecting> [IPv4 ('10.89.0.6', 29092)]>: connecting to broker:29092 [('10.89.0.6', 29092) IPv4]
[2025-06-16T13:43:01.292+0000] {conn.py:618} INFO - <BrokerConnection client_id=kafka-python-producer-1, node_id=bootstrap-0 host=broker:29092 <checking_api_versions_recv> [IPv4 ('10.89.0.6', 29092)]>: Broker version identified as 2.6
[2025-06-16T13:43:01.293+0000] {conn.py:457} INFO - <BrokerConnection client_id=kafka-python-producer-1, node_id=bootstrap-0 host=broker:29092 <connected> [IPv4 ('10.89.0.6', 29092)]>: Connection complete.
[2025-06-16T13:43:02.405+0000] {conn.py:396} INFO - <BrokerConnection client_id=kafka-python-producer-1, node_id=1 host=broker:29092 <connecting> [IPv4 ('10.89.0.6', 29092)]>: connecting to broker:29092 [('10.89.0.6', 29092) IPv4]
[2025-06-16T13:43:02.655+0000] {conn.py:457} INFO - <BrokerConnection client_id=kafka-python-producer-1, node_id=1 host=broker:29092 <connected> [IPv4 ('10.89.0.6', 29092)]>: Connection complete.
[2025-06-16T13:43:02.698+0000] {conn.py:945} INFO - <BrokerConnection client_id=kafka-python-producer-1, node_id=bootstrap-0 host=broker:29092 <connected> [IPv4 ('10.89.0.6', 29092)]>: Closing connection. 
[2025-06-16T13:43:03.537+0000] {cluster.py:313} WARNING - Topic users_created is not available during auto-create initialization
[2025-06-16T13:43:04.315+0000] {cluster.py:313} WARNING - Topic users_created is not available during auto-create initialization
[2025-06-16T13:43:05.129+0000] {cluster.py:313} WARNING - Topic users_created is not available during auto-create initialization
[2025-06-16T13:43:07.361+0000] {cluster.py:313} WARNING - Topic users_created is not available during auto-create initialization
[2025-06-16T13:43:07.416+0000] {kafka_stream.py:56} ERROR - an error occurred: KafkaTimeoutError: Failed to update metadata after 5.0 secs.
[2025-06-16T13:43:08.342+0000] {logging_mixin.py:149} INFO - an error occurred: KafkaTimeoutError: Failed to update metadata after 5.0 secs.
[2025-06-16T13:45:03.748+0000] {conn.py:945} ERROR - <BrokerConnection client_id=kafka-python-producer-1, node_id=1 host=broker:29092 <connected> [IPv4 ('10.89.0.6', 29092)]>: Closing connection. KafkaConnectionError: Socket EVENT_READ without in-flight-requests
[2025-06-16T13:45:05.023+0000] {kafka_stream.py:56} ERROR - an error occurred: HTTPSConnectionPool(host='randomuser.me', port=443): Max retries exceeded with url: /api/ (Caused by SSLError(SSLEOFError(8, 'EOF occurred in violation of protocol (_ssl.c:1129)')))
[2025-06-16T13:45:05.037+0000] {logging_mixin.py:149} INFO - an error occurred: HTTPSConnectionPool(host='randomuser.me', port=443): Max retries exceeded with url: /api/ (Caused by SSLError(SSLEOFError(8, 'EOF occurred in violation of protocol (_ssl.c:1129)')))
[2025-06-16T13:45:05.192+0000] {python.py:183} INFO - Done. Returned value was: None
[2025-06-16T13:45:05.675+0000] {taskinstance.py:1368} INFO - Marking task as SUCCESS. dag_id=user_automation, task_id=stream_data_from_api, execution_date=20250616T134256, start_date=20250616T134259, end_date=20250616T134505
[2025-06-16T13:45:05.916+0000] {local_task_job_runner.py:232} INFO - Task exited with return code 0
[2025-06-16T13:45:06.119+0000] {taskinstance.py:2674} INFO - 0 downstream tasks scheduled from follow-on schedule check
